<?xml version='1.0' encoding='UTF-8'?>
<robot name="scene">
  <link name="l_world">
    <inertial>
      <origin xyz="0.0 0.0 0.0" rpy="0.0 -0.0 0.0"/>
      <mass value="1.0"/>
      <inertia ixx="1.0" ixy="0.0" ixz="0.0" iyy="1.0" iyz="0.0" izz="1.0"/>
    </inertial>
  </link>
  <link name="l_3">
    <inertial>
      <origin xyz="0.0 0.0 0.0" rpy="0.0 -0.0 0.0"/>
      <mass value="25.754111999999996"/>
      <inertia ixx="1.0" ixy="0.0" ixz="0.0" iyy="1.0" iyz="0.0" izz="1.0"/>
    </inertial>
    <visual>
      <geometry>
        <mesh filename="objs/3.obj"/>
      </geometry>
      <origin xyz="0.0 0.0 0.0" rpy="0.0 -0.0 0.0"/>
    </visual>
  </link>
  <link name="l_5">
    <inertial>
      <origin xyz="0.0 0.0 0.0" rpy="0.0 -0.0 0.0"/>
      <mass value="2.925331199999999"/>
      <inertia ixx="1.0" ixy="0.0" ixz="0.0" iyy="1.0" iyz="0.0" izz="1.0"/>
    </inertial>
    <visual>
      <geometry>
        <mesh filename="objs/5.obj"/>
      </geometry>
      <origin xyz="0.0 0.0 0.0" rpy="0.0 -0.0 0.0"/>
    </visual>
  </link>
  <link name="l_2">
    <inertial>
      <origin xyz="0.0 0.0 0.0" rpy="0.0 -0.0 0.0"/>
      <mass value="11.869286399999996"/>
      <inertia ixx="1.0" ixy="0.0" ixz="0.0" iyy="1.0" iyz="0.0" izz="1.0"/>
    </inertial>
    <visual>
      <geometry>
        <mesh filename="objs/2.obj"/>
      </geometry>
      <origin xyz="0.0 0.0 0.0" rpy="0.0 -0.0 0.0"/>
    </visual>
  </link>
  <link name="l_1">
    <inertial>
      <origin xyz="0.0 0.0 0.0" rpy="0.0 -0.0 0.0"/>
      <mass value="55.31535359999999"/>
      <inertia ixx="1.0" ixy="0.0" ixz="0.0" iyy="1.0" iyz="0.0" izz="1.0"/>
    </inertial>
    <visual>
      <geometry>
        <mesh filename="objs/1.obj"/>
      </geometry>
      <origin xyz="0.0 0.0 0.0" rpy="0.0 -0.0 0.0"/>
    </visual>
  </link>
  <link name="l_4">
    <inertial>
      <origin xyz="0.0 0.0 0.0" rpy="0.0 -0.0 0.0"/>
      <mass value="115.27764479999998"/>
      <inertia ixx="1.0" ixy="0.0" ixz="0.0" iyy="1.0" iyz="0.0" izz="1.0"/>
    </inertial>
    <visual>
      <geometry>
        <mesh filename="objs/4.obj"/>
      </geometry>
      <origin xyz="0.0 0.0 0.0" rpy="0.0 -0.0 0.0"/>
    </visual>
  </link>
  <link name="l_6">
    <inertial>
      <origin xyz="0.0 0.0 0.0" rpy="0.0 -0.0 0.0"/>
      <mass value="41.850432"/>
      <inertia ixx="1.0" ixy="0.0" ixz="0.0" iyy="1.0" iyz="0.0" izz="1.0"/>
    </inertial>
    <visual>
      <geometry>
        <mesh filename="objs/6.obj"/>
      </geometry>
      <origin xyz="0.0 0.0 0.0" rpy="0.0 -0.0 0.0"/>
    </visual>
  </link>
  <joint name="fixed_3_5" type="fixed">
    <parent link="l_3"/>
    <child link="l_5"/>
    <axis xyz="1. 0. 0."/>
    <origin xyz="0.0 0.0 0.0" rpy="0.0 -0.0 0.0"/>
  </joint>
  <joint name="fixed_3_2" type="fixed">
    <parent link="l_3"/>
    <child link="l_2"/>
    <axis xyz="1. 0. 0."/>
    <origin xyz="0.0 0.0 0.0" rpy="0.0 -0.0 0.0"/>
  </joint>
  <joint name="fixed_3_1" type="fixed">
    <parent link="l_3"/>
    <child link="l_1"/>
    <axis xyz="1. 0. 0."/>
    <origin xyz="0.0 0.0 0.0" rpy="0.0 -0.0 0.0"/>
  </joint>
  <joint name="fixed_3_4" type="fixed">
    <parent link="l_3"/>
    <child link="l_4"/>
    <axis xyz="1. 0. 0."/>
    <origin xyz="0.0 0.0 0.0" rpy="0.0 -0.0 0.0"/>
  </joint>
  <joint name="fixed_3_6" type="fixed">
    <parent link="l_3"/>
    <child link="l_6"/>
    <axis xyz="1. 0. 0."/>
    <origin xyz="0.0 0.0 0.0" rpy="0.0 -0.0 0.0"/>
  </joint>
  <link name="l_0">
    <inertial>
      <origin xyz="-0.15545706450939178 -0.577844500541687 0.3376811146736145" rpy="0.0 -0.0 0.0"/>
      <mass value="89.85945599999998"/>
      <inertia ixx="1.0" ixy="0.0" ixz="0.0" iyy="1.0" iyz="0.0" izz="1.0"/>
    </inertial>
    <visual>
      <geometry>
        <mesh filename="objs/0.obj"/>
      </geometry>
      <origin xyz="-0.15545706450939178 -0.577844500541687 0.3376811146736145" rpy="0.0 -0.0 0.0"/>
    </visual>
  </link>
  <joint name="joint_revolute_3_0" type="revolute">
    <limit effort="2000.0" velocity="2.0" lower="-0.17453292649980456" upper="0.0"/>
    <parent link="l_3"/>
    <child link="l_0"/>
    <axis xyz="-1 0 0"/>
    <origin xyz="0.15545706450939178 0.577844500541687 -0.3376811146736145" rpy="0.0 -0.0 0.0"/>
  </joint>
  <link name="l_7">
    <inertial>
      <origin xyz="0.010322020389139652 0.2736789882183075 -0.20026616752147675" rpy="0.0 -0.0 0.0"/>
      <mass value="161.94297599999996"/>
      <inertia ixx="1.0" ixy="0.0" ixz="0.0" iyy="1.0" iyz="0.0" izz="1.0"/>
    </inertial>
    <visual>
      <geometry>
        <mesh filename="objs/7.obj"/>
      </geometry>
      <origin xyz="0.010322020389139652 0.2736789882183075 -0.20026616752147675" rpy="0.0 -0.0 0.0"/>
    </visual>
  </link>
  <joint name="joint_revolute_3_7" type="revolute">
    <limit effort="2000.0" velocity="2.0" lower="-3.141592653589793" upper="3.141592653589793"/>
    <parent link="joint_movrotcenter_3_7"/>
    <child link="l_7"/>
    <axis xyz="0 1 0"/>
    <origin xyz="-0.010322020389139652 -0.2736789882183075 0.20026616752147675" rpy="0.0 -0.0 0.0"/>
  </joint>
  <link name="joint_movrotcenter_3_7">
    <visual><geometry><sphere radius="0.00001"/></geometry><origin xyz="-0.010322020389139652 -0.2736789882183075 0.20026616752147675" rpy="0.0 -0.0 0.0"/></visual>
  </link>
  <joint name="movrotcenter_3_7" type="prismatic">
    <limit effort="2000.0" velocity="2.0" lower="0.0" upper="0.06813796"/>
    <parent link="l_3"/>
    <child link="joint_movrotcenter_3_7"/>
    <axis xyz="0 1 0"/>
    <origin xyz="0.0 0.0 -0.0" rpy="0.0 -0.0 0.0"/>
  </joint>
</robot>
