<?xml version='1.0' encoding='UTF-8'?>
<robot name="scene">
  <link name="l_world">
    <inertial>
      <origin xyz="0.0 0.0 0.0" rpy="0.0 -0.0 0.0"/>
      <mass value="1.0"/>
      <inertia ixx="1.0" ixy="0.0" ixz="0.0" iyy="1.0" iyz="0.0" izz="1.0"/>
    </inertial>
  </link>
  <link name="l_99">
    <inertial>
      <origin xyz="0.0 0.0 0.0" rpy="0.0 -0.0 0.0"/>
      <mass value="0.08279884799999998"/>
      <inertia ixx="1.0" ixy="0.0" ixz="0.0" iyy="1.0" iyz="0.0" izz="1.0"/>
    </inertial>
    <visual>
      <geometry>
        <mesh filename="objs/99.obj"/>
      </geometry>
      <origin xyz="0.0 0.0 0.0" rpy="0.0 -0.0 0.0"/>
    </visual>
  </link>
  <link name="l_100">
    <inertial>
      <origin xyz="0.0 0.0 0.0" rpy="0.0 -0.0 0.0"/>
      <mass value="0.08831877119999998"/>
      <inertia ixx="1.0" ixy="0.0" ixz="0.0" iyy="1.0" iyz="0.0" izz="1.0"/>
    </inertial>
    <visual>
      <geometry>
        <mesh filename="objs/100.obj"/>
      </geometry>
      <origin xyz="0.0 0.0 0.0" rpy="0.0 -0.0 0.0"/>
    </visual>
  </link>
  <joint name="fixed_99_100" type="fixed">
    <parent link="l_99"/>
    <child link="l_100"/>
    <axis xyz="1. 0. 0."/>
    <origin xyz="0.0 0.0 0.0" rpy="0.0 -0.0 0.0"/>
  </joint>
  <link name="l_0">
    <inertial>
      <origin xyz="0.0 0.0 0.0" rpy="0.0 -0.0 0.0"/>
      <mass value="0.040663434240000004"/>
      <inertia ixx="1.0" ixy="0.0" ixz="0.0" iyy="1.0" iyz="0.0" izz="1.0"/>
    </inertial>
    <visual>
      <geometry>
        <mesh filename="objs/0.obj"/>
      </geometry>
      <origin xyz="0.0 0.0 0.0" rpy="0.0 -0.0 0.0"/>
    </visual>
  </link>
  <joint name="joint_revolute_99_0" type="prismatic">
    <limit effort="2000.0" velocity="2.0" lower="-0.0199964" upper="0.0"/>
    <parent link="l_99"/>
    <child link="l_0"/>
    <axis xyz="0 1 0"/>
    <origin xyz="0.0 0.0 -0.0" rpy="0.0 -0.0 0.0"/>
  </joint>
  <link name="l_1">
    <inertial>
      <origin xyz="0.0 0.0 0.0" rpy="0.0 -0.0 0.0"/>
      <mass value="0.043055400960000004"/>
      <inertia ixx="1.0" ixy="0.0" ixz="0.0" iyy="1.0" iyz="0.0" izz="1.0"/>
    </inertial>
    <visual>
      <geometry>
        <mesh filename="objs/1.obj"/>
      </geometry>
      <origin xyz="0.0 0.0 0.0" rpy="0.0 -0.0 0.0"/>
    </visual>
  </link>
  <joint name="joint_revolute_99_1" type="prismatic">
    <limit effort="2000.0" velocity="2.0" lower="-0.0199964" upper="0.0"/>
    <parent link="l_99"/>
    <child link="l_1"/>
    <axis xyz="0 1 0"/>
    <origin xyz="0.0 0.0 -0.0" rpy="0.0 -0.0 0.0"/>
  </joint>
  <link name="l_2">
    <inertial>
      <origin xyz="0.0 0.0 0.0" rpy="0.0 -0.0 0.0"/>
      <mass value="0.05501523456"/>
      <inertia ixx="1.0" ixy="0.0" ixz="0.0" iyy="1.0" iyz="0.0" izz="1.0"/>
    </inertial>
    <visual>
      <geometry>
        <mesh filename="objs/2.obj"/>
      </geometry>
      <origin xyz="0.0 0.0 0.0" rpy="0.0 -0.0 0.0"/>
    </visual>
  </link>
  <joint name="joint_revolute_99_2" type="prismatic">
    <limit effort="2000.0" velocity="2.0" lower="-0.0199964" upper="0.0"/>
    <parent link="l_99"/>
    <child link="l_2"/>
    <axis xyz="0 1 0"/>
    <origin xyz="0.0 0.0 -0.0" rpy="0.0 -0.0 0.0"/>
  </joint>
  <link name="l_3">
    <inertial>
      <origin xyz="0.0 0.0 0.0" rpy="0.0 -0.0 0.0"/>
      <mass value="0.05740720128"/>
      <inertia ixx="1.0" ixy="0.0" ixz="0.0" iyy="1.0" iyz="0.0" izz="1.0"/>
    </inertial>
    <visual>
      <geometry>
        <mesh filename="objs/3.obj"/>
      </geometry>
      <origin xyz="0.0 0.0 0.0" rpy="0.0 -0.0 0.0"/>
    </visual>
  </link>
  <joint name="joint_revolute_99_3" type="prismatic">
    <limit effort="2000.0" velocity="2.0" lower="-0.0199964" upper="0.0"/>
    <parent link="l_99"/>
    <child link="l_3"/>
    <axis xyz="0 1 0"/>
    <origin xyz="0.0 0.0 -0.0" rpy="0.0 -0.0 0.0"/>
  </joint>
  <link name="l_4">
    <inertial>
      <origin xyz="0.0 0.0 0.0" rpy="0.0 -0.0 0.0"/>
      <mass value="0.05501523456"/>
      <inertia ixx="1.0" ixy="0.0" ixz="0.0" iyy="1.0" iyz="0.0" izz="1.0"/>
    </inertial>
    <visual>
      <geometry>
        <mesh filename="objs/4.obj"/>
      </geometry>
      <origin xyz="0.0 0.0 0.0" rpy="0.0 -0.0 0.0"/>
    </visual>
  </link>
  <joint name="joint_revolute_99_4" type="prismatic">
    <limit effort="2000.0" velocity="2.0" lower="-0.0199964" upper="0.0"/>
    <parent link="l_99"/>
    <child link="l_4"/>
    <axis xyz="0 1 0"/>
    <origin xyz="0.0 0.0 -0.0" rpy="0.0 -0.0 0.0"/>
  </joint>
  <link name="l_5">
    <inertial>
      <origin xyz="0.0 0.0 0.0" rpy="0.0 -0.0 0.0"/>
      <mass value="0.059799168"/>
      <inertia ixx="1.0" ixy="0.0" ixz="0.0" iyy="1.0" iyz="0.0" izz="1.0"/>
    </inertial>
    <visual>
      <geometry>
        <mesh filename="objs/5.obj"/>
      </geometry>
      <origin xyz="0.0 0.0 0.0" rpy="0.0 -0.0 0.0"/>
    </visual>
  </link>
  <joint name="joint_revolute_99_5" type="prismatic">
    <limit effort="2000.0" velocity="2.0" lower="-0.0199964" upper="0.0"/>
    <parent link="l_99"/>
    <child link="l_5"/>
    <axis xyz="0 1 0"/>
    <origin xyz="0.0 0.0 -0.0" rpy="0.0 -0.0 0.0"/>
  </joint>
  <link name="l_6">
    <inertial>
      <origin xyz="0.0 0.0 0.0" rpy="0.0 -0.0 0.0"/>
      <mass value="0.059799168"/>
      <inertia ixx="1.0" ixy="0.0" ixz="0.0" iyy="1.0" iyz="0.0" izz="1.0"/>
    </inertial>
    <visual>
      <geometry>
        <mesh filename="objs/6.obj"/>
      </geometry>
      <origin xyz="0.0 0.0 0.0" rpy="0.0 -0.0 0.0"/>
    </visual>
  </link>
  <joint name="joint_revolute_99_6" type="prismatic">
    <limit effort="2000.0" velocity="2.0" lower="-0.0199964" upper="0.0"/>
    <parent link="l_99"/>
    <child link="l_6"/>
    <axis xyz="0 1 0"/>
    <origin xyz="0.0 0.0 -0.0" rpy="0.0 -0.0 0.0"/>
  </joint>
  <link name="l_7">
    <inertial>
      <origin xyz="0.0 0.0 0.0" rpy="0.0 -0.0 0.0"/>
      <mass value="0.06219113472"/>
      <inertia ixx="1.0" ixy="0.0" ixz="0.0" iyy="1.0" iyz="0.0" izz="1.0"/>
    </inertial>
    <visual>
      <geometry>
        <mesh filename="objs/7.obj"/>
      </geometry>
      <origin xyz="0.0 0.0 0.0" rpy="0.0 -0.0 0.0"/>
    </visual>
  </link>
  <joint name="joint_revolute_99_7" type="prismatic">
    <limit effort="2000.0" velocity="2.0" lower="-0.0199964" upper="0.0"/>
    <parent link="l_99"/>
    <child link="l_7"/>
    <axis xyz="0 1 0"/>
    <origin xyz="0.0 0.0 -0.0" rpy="0.0 -0.0 0.0"/>
  </joint>
  <link name="l_8">
    <inertial>
      <origin xyz="0.0 0.0 0.0" rpy="0.0 -0.0 0.0"/>
      <mass value="0.10285456895999998"/>
      <inertia ixx="1.0" ixy="0.0" ixz="0.0" iyy="1.0" iyz="0.0" izz="1.0"/>
    </inertial>
    <visual>
      <geometry>
        <mesh filename="objs/8.obj"/>
      </geometry>
      <origin xyz="0.0 0.0 0.0" rpy="0.0 -0.0 0.0"/>
    </visual>
  </link>
  <joint name="joint_revolute_99_8" type="prismatic">
    <limit effort="2000.0" velocity="2.0" lower="-0.0199964" upper="0.0"/>
    <parent link="l_99"/>
    <child link="l_8"/>
    <axis xyz="0 1 0"/>
    <origin xyz="0.0 0.0 -0.0" rpy="0.0 -0.0 0.0"/>
  </joint>
  <link name="l_9">
    <inertial>
      <origin xyz="0.0 0.0 0.0" rpy="0.0 -0.0 0.0"/>
      <mass value="0.06697506815999998"/>
      <inertia ixx="1.0" ixy="0.0" ixz="0.0" iyy="1.0" iyz="0.0" izz="1.0"/>
    </inertial>
    <visual>
      <geometry>
        <mesh filename="objs/9.obj"/>
      </geometry>
      <origin xyz="0.0 0.0 0.0" rpy="0.0 -0.0 0.0"/>
    </visual>
  </link>
  <joint name="joint_revolute_99_9" type="prismatic">
    <limit effort="2000.0" velocity="2.0" lower="-0.0199964" upper="0.0"/>
    <parent link="l_99"/>
    <child link="l_9"/>
    <axis xyz="0 1 0"/>
    <origin xyz="0.0 0.0 -0.0" rpy="0.0 -0.0 0.0"/>
  </joint>
  <link name="l_10">
    <inertial>
      <origin xyz="0.0 0.0 0.0" rpy="0.0 -0.0 0.0"/>
      <mass value="0.05501523456"/>
      <inertia ixx="1.0" ixy="0.0" ixz="0.0" iyy="1.0" iyz="0.0" izz="1.0"/>
    </inertial>
    <visual>
      <geometry>
        <mesh filename="objs/10.obj"/>
      </geometry>
      <origin xyz="0.0 0.0 0.0" rpy="0.0 -0.0 0.0"/>
    </visual>
  </link>
  <joint name="joint_revolute_99_10" type="prismatic">
    <limit effort="2000.0" velocity="2.0" lower="-0.0199964" upper="0.0"/>
    <parent link="l_99"/>
    <child link="l_10"/>
    <axis xyz="0 1 0"/>
    <origin xyz="0.0 0.0 -0.0" rpy="0.0 -0.0 0.0"/>
  </joint>
  <link name="l_11">
    <inertial>
      <origin xyz="0.0 0.0 0.0" rpy="0.0 -0.0 0.0"/>
      <mass value="0.05501523456"/>
      <inertia ixx="1.0" ixy="0.0" ixz="0.0" iyy="1.0" iyz="0.0" izz="1.0"/>
    </inertial>
    <visual>
      <geometry>
        <mesh filename="objs/11.obj"/>
      </geometry>
      <origin xyz="0.0 0.0 0.0" rpy="0.0 -0.0 0.0"/>
    </visual>
  </link>
  <joint name="joint_revolute_99_11" type="prismatic">
    <limit effort="2000.0" velocity="2.0" lower="-0.0199964" upper="0.0"/>
    <parent link="l_99"/>
    <child link="l_11"/>
    <axis xyz="0 1 0"/>
    <origin xyz="0.0 0.0 -0.0" rpy="0.0 -0.0 0.0"/>
  </joint>
  <link name="l_12">
    <inertial>
      <origin xyz="0.0 0.0 0.0" rpy="0.0 -0.0 0.0"/>
      <mass value="0.043055400960000004"/>
      <inertia ixx="1.0" ixy="0.0" ixz="0.0" iyy="1.0" iyz="0.0" izz="1.0"/>
    </inertial>
    <visual>
      <geometry>
        <mesh filename="objs/12.obj"/>
      </geometry>
      <origin xyz="0.0 0.0 0.0" rpy="0.0 -0.0 0.0"/>
    </visual>
  </link>
  <joint name="joint_revolute_99_12" type="prismatic">
    <limit effort="2000.0" velocity="2.0" lower="-0.0199964" upper="0.0"/>
    <parent link="l_99"/>
    <child link="l_12"/>
    <axis xyz="0 1 0"/>
    <origin xyz="0.0 0.0 -0.0" rpy="0.0 -0.0 0.0"/>
  </joint>
  <link name="l_13">
    <inertial>
      <origin xyz="0.0 0.0 0.0" rpy="0.0 -0.0 0.0"/>
      <mass value="0.06219113472"/>
      <inertia ixx="1.0" ixy="0.0" ixz="0.0" iyy="1.0" iyz="0.0" izz="1.0"/>
    </inertial>
    <visual>
      <geometry>
        <mesh filename="objs/13.obj"/>
      </geometry>
      <origin xyz="0.0 0.0 0.0" rpy="0.0 -0.0 0.0"/>
    </visual>
  </link>
  <joint name="joint_revolute_99_13" type="prismatic">
    <limit effort="2000.0" velocity="2.0" lower="-0.0199964" upper="0.0"/>
    <parent link="l_99"/>
    <child link="l_13"/>
    <axis xyz="0 1 0"/>
    <origin xyz="0.0 0.0 -0.0" rpy="0.0 -0.0 0.0"/>
  </joint>
  <link name="l_14">
    <inertial>
      <origin xyz="0.0 0.0 0.0" rpy="0.0 -0.0 0.0"/>
      <mass value="0.14590996992000002"/>
      <inertia ixx="1.0" ixy="0.0" ixz="0.0" iyy="1.0" iyz="0.0" izz="1.0"/>
    </inertial>
    <visual>
      <geometry>
        <mesh filename="objs/14.obj"/>
      </geometry>
      <origin xyz="0.0 0.0 0.0" rpy="0.0 -0.0 0.0"/>
    </visual>
  </link>
  <joint name="joint_revolute_99_14" type="prismatic">
    <limit effort="2000.0" velocity="2.0" lower="-0.0199964" upper="0.0"/>
    <parent link="l_99"/>
    <child link="l_14"/>
    <axis xyz="0 1 0"/>
    <origin xyz="0.0 0.0 -0.0" rpy="0.0 -0.0 0.0"/>
  </joint>
  <link name="l_15">
    <inertial>
      <origin xyz="0.0 0.0 0.0" rpy="0.0 -0.0 0.0"/>
      <mass value="0.047839334399999996"/>
      <inertia ixx="1.0" ixy="0.0" ixz="0.0" iyy="1.0" iyz="0.0" izz="1.0"/>
    </inertial>
    <visual>
      <geometry>
        <mesh filename="objs/15.obj"/>
      </geometry>
      <origin xyz="0.0 0.0 0.0" rpy="0.0 -0.0 0.0"/>
    </visual>
  </link>
  <joint name="joint_revolute_99_15" type="prismatic">
    <limit effort="2000.0" velocity="2.0" lower="-0.0199964" upper="0.0"/>
    <parent link="l_99"/>
    <child link="l_15"/>
    <axis xyz="0 1 0"/>
    <origin xyz="0.0 0.0 -0.0" rpy="0.0 -0.0 0.0"/>
  </joint>
  <link name="l_16">
    <inertial>
      <origin xyz="0.0 0.0 0.0" rpy="0.0 -0.0 0.0"/>
      <mass value="0.05262326784"/>
      <inertia ixx="1.0" ixy="0.0" ixz="0.0" iyy="1.0" iyz="0.0" izz="1.0"/>
    </inertial>
    <visual>
      <geometry>
        <mesh filename="objs/16.obj"/>
      </geometry>
      <origin xyz="0.0 0.0 0.0" rpy="0.0 -0.0 0.0"/>
    </visual>
  </link>
  <joint name="joint_revolute_99_16" type="prismatic">
    <limit effort="2000.0" velocity="2.0" lower="-0.0199964" upper="0.0"/>
    <parent link="l_99"/>
    <child link="l_16"/>
    <axis xyz="0 1 0"/>
    <origin xyz="0.0 0.0 -0.0" rpy="0.0 -0.0 0.0"/>
  </joint>
  <link name="l_17">
    <inertial>
      <origin xyz="0.0 0.0 0.0" rpy="0.0 -0.0 0.0"/>
      <mass value="0.06219113472"/>
      <inertia ixx="1.0" ixy="0.0" ixz="0.0" iyy="1.0" iyz="0.0" izz="1.0"/>
    </inertial>
    <visual>
      <geometry>
        <mesh filename="objs/17.obj"/>
      </geometry>
      <origin xyz="0.0 0.0 0.0" rpy="0.0 -0.0 0.0"/>
    </visual>
  </link>
  <joint name="joint_revolute_99_17" type="prismatic">
    <limit effort="2000.0" velocity="2.0" lower="-0.0199964" upper="0.0"/>
    <parent link="l_99"/>
    <child link="l_17"/>
    <axis xyz="0 1 0"/>
    <origin xyz="0.0 0.0 -0.0" rpy="0.0 -0.0 0.0"/>
  </joint>
  <link name="l_18">
    <inertial>
      <origin xyz="0.0 0.0 0.0" rpy="0.0 -0.0 0.0"/>
      <mass value="0.059799168"/>
      <inertia ixx="1.0" ixy="0.0" ixz="0.0" iyy="1.0" iyz="0.0" izz="1.0"/>
    </inertial>
    <visual>
      <geometry>
        <mesh filename="objs/18.obj"/>
      </geometry>
      <origin xyz="0.0 0.0 0.0" rpy="0.0 -0.0 0.0"/>
    </visual>
  </link>
  <joint name="joint_revolute_99_18" type="prismatic">
    <limit effort="2000.0" velocity="2.0" lower="-0.0199964" upper="0.0"/>
    <parent link="l_99"/>
    <child link="l_18"/>
    <axis xyz="0 1 0"/>
    <origin xyz="0.0 0.0 -0.0" rpy="0.0 -0.0 0.0"/>
  </joint>
  <link name="l_19">
    <inertial>
      <origin xyz="0.0 0.0 0.0" rpy="0.0 -0.0 0.0"/>
      <mass value="0.06219113472"/>
      <inertia ixx="1.0" ixy="0.0" ixz="0.0" iyy="1.0" iyz="0.0" izz="1.0"/>
    </inertial>
    <visual>
      <geometry>
        <mesh filename="objs/19.obj"/>
      </geometry>
      <origin xyz="0.0 0.0 0.0" rpy="0.0 -0.0 0.0"/>
    </visual>
  </link>
  <joint name="joint_revolute_99_19" type="prismatic">
    <limit effort="2000.0" velocity="2.0" lower="-0.0199964" upper="0.0"/>
    <parent link="l_99"/>
    <child link="l_19"/>
    <axis xyz="0 1 0"/>
    <origin xyz="0.0 0.0 -0.0" rpy="0.0 -0.0 0.0"/>
  </joint>
  <link name="l_20">
    <inertial>
      <origin xyz="0.0 0.0 0.0" rpy="0.0 -0.0 0.0"/>
      <mass value="0.07893490176"/>
      <inertia ixx="1.0" ixy="0.0" ixz="0.0" iyy="1.0" iyz="0.0" izz="1.0"/>
    </inertial>
    <visual>
      <geometry>
        <mesh filename="objs/20.obj"/>
      </geometry>
      <origin xyz="0.0 0.0 0.0" rpy="0.0 -0.0 0.0"/>
    </visual>
  </link>
  <joint name="joint_revolute_99_20" type="prismatic">
    <limit effort="2000.0" velocity="2.0" lower="-0.0199964" upper="0.0"/>
    <parent link="l_99"/>
    <child link="l_20"/>
    <axis xyz="0 1 0"/>
    <origin xyz="0.0 0.0 -0.0" rpy="0.0 -0.0 0.0"/>
  </joint>
  <link name="l_21">
    <inertial>
      <origin xyz="0.0 0.0 0.0" rpy="0.0 -0.0 0.0"/>
      <mass value="0.05740720128"/>
      <inertia ixx="1.0" ixy="0.0" ixz="0.0" iyy="1.0" iyz="0.0" izz="1.0"/>
    </inertial>
    <visual>
      <geometry>
        <mesh filename="objs/21.obj"/>
      </geometry>
      <origin xyz="0.0 0.0 0.0" rpy="0.0 -0.0 0.0"/>
    </visual>
  </link>
  <joint name="joint_revolute_99_21" type="prismatic">
    <limit effort="2000.0" velocity="2.0" lower="-0.0199964" upper="0.0"/>
    <parent link="l_99"/>
    <child link="l_21"/>
    <axis xyz="0 1 0"/>
    <origin xyz="0.0 0.0 -0.0" rpy="0.0 -0.0 0.0"/>
  </joint>
  <link name="l_22">
    <inertial>
      <origin xyz="0.0 0.0 0.0" rpy="0.0 -0.0 0.0"/>
      <mass value="0.05262326784"/>
      <inertia ixx="1.0" ixy="0.0" ixz="0.0" iyy="1.0" iyz="0.0" izz="1.0"/>
    </inertial>
    <visual>
      <geometry>
        <mesh filename="objs/22.obj"/>
      </geometry>
      <origin xyz="0.0 0.0 0.0" rpy="0.0 -0.0 0.0"/>
    </visual>
  </link>
  <joint name="joint_revolute_99_22" type="prismatic">
    <limit effort="2000.0" velocity="2.0" lower="-0.0199964" upper="0.0"/>
    <parent link="l_99"/>
    <child link="l_22"/>
    <axis xyz="0 1 0"/>
    <origin xyz="0.0 0.0 -0.0" rpy="0.0 -0.0 0.0"/>
  </joint>
  <link name="l_23">
    <inertial>
      <origin xyz="0.0 0.0 0.0" rpy="0.0 -0.0 0.0"/>
      <mass value="0.11003046912"/>
      <inertia ixx="1.0" ixy="0.0" ixz="0.0" iyy="1.0" iyz="0.0" izz="1.0"/>
    </inertial>
    <visual>
      <geometry>
        <mesh filename="objs/23.obj"/>
      </geometry>
      <origin xyz="0.0 0.0 0.0" rpy="0.0 -0.0 0.0"/>
    </visual>
  </link>
  <joint name="joint_revolute_99_23" type="prismatic">
    <limit effort="2000.0" velocity="2.0" lower="-0.0199964" upper="0.0"/>
    <parent link="l_99"/>
    <child link="l_23"/>
    <axis xyz="0 1 0"/>
    <origin xyz="0.0 0.0 -0.0" rpy="0.0 -0.0 0.0"/>
  </joint>
  <link name="l_24">
    <inertial>
      <origin xyz="0.0 0.0 0.0" rpy="0.0 -0.0 0.0"/>
      <mass value="0.05740720128"/>
      <inertia ixx="1.0" ixy="0.0" ixz="0.0" iyy="1.0" iyz="0.0" izz="1.0"/>
    </inertial>
    <visual>
      <geometry>
        <mesh filename="objs/24.obj"/>
      </geometry>
      <origin xyz="0.0 0.0 0.0" rpy="0.0 -0.0 0.0"/>
    </visual>
  </link>
  <joint name="joint_revolute_99_24" type="prismatic">
    <limit effort="2000.0" velocity="2.0" lower="-0.0199964" upper="0.0"/>
    <parent link="l_99"/>
    <child link="l_24"/>
    <axis xyz="0 1 0"/>
    <origin xyz="0.0 0.0 -0.0" rpy="0.0 -0.0 0.0"/>
  </joint>
  <link name="l_25">
    <inertial>
      <origin xyz="0.0 0.0 0.0" rpy="0.0 -0.0 0.0"/>
      <mass value="0.045447367679999996"/>
      <inertia ixx="1.0" ixy="0.0" ixz="0.0" iyy="1.0" iyz="0.0" izz="1.0"/>
    </inertial>
    <visual>
      <geometry>
        <mesh filename="objs/25.obj"/>
      </geometry>
      <origin xyz="0.0 0.0 0.0" rpy="0.0 -0.0 0.0"/>
    </visual>
  </link>
  <joint name="joint_revolute_99_25" type="prismatic">
    <limit effort="2000.0" velocity="2.0" lower="-0.0199964" upper="0.0"/>
    <parent link="l_99"/>
    <child link="l_25"/>
    <axis xyz="0 1 0"/>
    <origin xyz="0.0 0.0 -0.0" rpy="0.0 -0.0 0.0"/>
  </joint>
  <link name="l_26">
    <inertial>
      <origin xyz="0.0 0.0 0.0" rpy="0.0 -0.0 0.0"/>
      <mass value="0.05262326784"/>
      <inertia ixx="1.0" ixy="0.0" ixz="0.0" iyy="1.0" iyz="0.0" izz="1.0"/>
    </inertial>
    <visual>
      <geometry>
        <mesh filename="objs/26.obj"/>
      </geometry>
      <origin xyz="0.0 0.0 0.0" rpy="0.0 -0.0 0.0"/>
    </visual>
  </link>
  <joint name="joint_revolute_99_26" type="prismatic">
    <limit effort="2000.0" velocity="2.0" lower="-0.0199964" upper="0.0"/>
    <parent link="l_99"/>
    <child link="l_26"/>
    <axis xyz="0 1 0"/>
    <origin xyz="0.0 0.0 -0.0" rpy="0.0 -0.0 0.0"/>
  </joint>
  <link name="l_27">
    <inertial>
      <origin xyz="0.0 0.0 0.0" rpy="0.0 -0.0 0.0"/>
      <mass value="11.46469648896"/>
      <inertia ixx="1.0" ixy="0.0" ixz="0.0" iyy="1.0" iyz="0.0" izz="1.0"/>
    </inertial>
    <visual>
      <geometry>
        <mesh filename="objs/27.obj"/>
      </geometry>
      <origin xyz="0.0 0.0 0.0" rpy="0.0 -0.0 0.0"/>
    </visual>
  </link>
  <joint name="joint_revolute_99_27" type="prismatic">
    <limit effort="2000.0" velocity="2.0" lower="-0.0199964" upper="0.0"/>
    <parent link="l_99"/>
    <child link="l_27"/>
    <axis xyz="0 1 0"/>
    <origin xyz="0.0 0.0 -0.0" rpy="0.0 -0.0 0.0"/>
  </joint>
  <link name="l_28">
    <inertial>
      <origin xyz="0.0 0.0 0.0" rpy="0.0 -0.0 0.0"/>
      <mass value="0.05501523456"/>
      <inertia ixx="1.0" ixy="0.0" ixz="0.0" iyy="1.0" iyz="0.0" izz="1.0"/>
    </inertial>
    <visual>
      <geometry>
        <mesh filename="objs/28.obj"/>
      </geometry>
      <origin xyz="0.0 0.0 0.0" rpy="0.0 -0.0 0.0"/>
    </visual>
  </link>
  <joint name="joint_revolute_99_28" type="prismatic">
    <limit effort="2000.0" velocity="2.0" lower="-0.0199964" upper="0.0"/>
    <parent link="l_99"/>
    <child link="l_28"/>
    <axis xyz="0 1 0"/>
    <origin xyz="0.0 0.0 -0.0" rpy="0.0 -0.0 0.0"/>
  </joint>
  <link name="l_29">
    <inertial>
      <origin xyz="0.0 0.0 0.0" rpy="0.0 -0.0 0.0"/>
      <mass value="0.06219113472"/>
      <inertia ixx="1.0" ixy="0.0" ixz="0.0" iyy="1.0" iyz="0.0" izz="1.0"/>
    </inertial>
    <visual>
      <geometry>
        <mesh filename="objs/29.obj"/>
      </geometry>
      <origin xyz="0.0 0.0 0.0" rpy="0.0 -0.0 0.0"/>
    </visual>
  </link>
  <joint name="joint_revolute_99_29" type="prismatic">
    <limit effort="2000.0" velocity="2.0" lower="-0.0199964" upper="0.0"/>
    <parent link="l_99"/>
    <child link="l_29"/>
    <axis xyz="0 1 0"/>
    <origin xyz="0.0 0.0 -0.0" rpy="0.0 -0.0 0.0"/>
  </joint>
  <link name="l_30">
    <inertial>
      <origin xyz="0.0 0.0 0.0" rpy="0.0 -0.0 0.0"/>
      <mass value="0.045447367679999996"/>
      <inertia ixx="1.0" ixy="0.0" ixz="0.0" iyy="1.0" iyz="0.0" izz="1.0"/>
    </inertial>
    <visual>
      <geometry>
        <mesh filename="objs/30.obj"/>
      </geometry>
      <origin xyz="0.0 0.0 0.0" rpy="0.0 -0.0 0.0"/>
    </visual>
  </link>
  <joint name="joint_revolute_99_30" type="prismatic">
    <limit effort="2000.0" velocity="2.0" lower="-0.0199964" upper="0.0"/>
    <parent link="l_99"/>
    <child link="l_30"/>
    <axis xyz="0 1 0"/>
    <origin xyz="0.0 0.0 -0.0" rpy="0.0 -0.0 0.0"/>
  </joint>
  <link name="l_31">
    <inertial>
      <origin xyz="0.0 0.0 0.0" rpy="0.0 -0.0 0.0"/>
      <mass value="0.05262326784"/>
      <inertia ixx="1.0" ixy="0.0" ixz="0.0" iyy="1.0" iyz="0.0" izz="1.0"/>
    </inertial>
    <visual>
      <geometry>
        <mesh filename="objs/31.obj"/>
      </geometry>
      <origin xyz="0.0 0.0 0.0" rpy="0.0 -0.0 0.0"/>
    </visual>
  </link>
  <joint name="joint_revolute_99_31" type="prismatic">
    <limit effort="2000.0" velocity="2.0" lower="-0.0199964" upper="0.0"/>
    <parent link="l_99"/>
    <child link="l_31"/>
    <axis xyz="0 1 0"/>
    <origin xyz="0.0 0.0 -0.0" rpy="0.0 -0.0 0.0"/>
  </joint>
  <link name="l_32">
    <inertial>
      <origin xyz="0.0 0.0 0.0" rpy="0.0 -0.0 0.0"/>
      <mass value="0.07415096832"/>
      <inertia ixx="1.0" ixy="0.0" ixz="0.0" iyy="1.0" iyz="0.0" izz="1.0"/>
    </inertial>
    <visual>
      <geometry>
        <mesh filename="objs/32.obj"/>
      </geometry>
      <origin xyz="0.0 0.0 0.0" rpy="0.0 -0.0 0.0"/>
    </visual>
  </link>
  <joint name="joint_revolute_99_32" type="prismatic">
    <limit effort="2000.0" velocity="2.0" lower="-0.0199964" upper="0.0"/>
    <parent link="l_99"/>
    <child link="l_32"/>
    <axis xyz="0 1 0"/>
    <origin xyz="0.0 0.0 -0.0" rpy="0.0 -0.0 0.0"/>
  </joint>
  <link name="l_33">
    <inertial>
      <origin xyz="0.0 0.0 0.0" rpy="0.0 -0.0 0.0"/>
      <mass value="0.09807063552"/>
      <inertia ixx="1.0" ixy="0.0" ixz="0.0" iyy="1.0" iyz="0.0" izz="1.0"/>
    </inertial>
    <visual>
      <geometry>
        <mesh filename="objs/33.obj"/>
      </geometry>
      <origin xyz="0.0 0.0 0.0" rpy="0.0 -0.0 0.0"/>
    </visual>
  </link>
  <joint name="joint_revolute_99_33" type="prismatic">
    <limit effort="2000.0" velocity="2.0" lower="-0.0199964" upper="0.0"/>
    <parent link="l_99"/>
    <child link="l_33"/>
    <axis xyz="0 1 0"/>
    <origin xyz="0.0 0.0 -0.0" rpy="0.0 -0.0 0.0"/>
  </joint>
  <link name="l_34">
    <inertial>
      <origin xyz="0.0 0.0 0.0" rpy="0.0 -0.0 0.0"/>
      <mass value="0.050231301119999995"/>
      <inertia ixx="1.0" ixy="0.0" ixz="0.0" iyy="1.0" iyz="0.0" izz="1.0"/>
    </inertial>
    <visual>
      <geometry>
        <mesh filename="objs/34.obj"/>
      </geometry>
      <origin xyz="0.0 0.0 0.0" rpy="0.0 -0.0 0.0"/>
    </visual>
  </link>
  <joint name="joint_revolute_99_34" type="prismatic">
    <limit effort="2000.0" velocity="2.0" lower="-0.0199964" upper="0.0"/>
    <parent link="l_99"/>
    <child link="l_34"/>
    <axis xyz="0 1 0"/>
    <origin xyz="0.0 0.0 -0.0" rpy="0.0 -0.0 0.0"/>
  </joint>
  <link name="l_35">
    <inertial>
      <origin xyz="0.0 0.0 0.0" rpy="0.0 -0.0 0.0"/>
      <mass value="0.040663434240000004"/>
      <inertia ixx="1.0" ixy="0.0" ixz="0.0" iyy="1.0" iyz="0.0" izz="1.0"/>
    </inertial>
    <visual>
      <geometry>
        <mesh filename="objs/35.obj"/>
      </geometry>
      <origin xyz="0.0 0.0 0.0" rpy="0.0 -0.0 0.0"/>
    </visual>
  </link>
  <joint name="joint_revolute_99_35" type="prismatic">
    <limit effort="2000.0" velocity="2.0" lower="-0.0199964" upper="0.0"/>
    <parent link="l_99"/>
    <child link="l_35"/>
    <axis xyz="0 1 0"/>
    <origin xyz="0.0 0.0 -0.0" rpy="0.0 -0.0 0.0"/>
  </joint>
  <link name="l_36">
    <inertial>
      <origin xyz="0.0 0.0 0.0" rpy="0.0 -0.0 0.0"/>
      <mass value="0.07654293504"/>
      <inertia ixx="1.0" ixy="0.0" ixz="0.0" iyy="1.0" iyz="0.0" izz="1.0"/>
    </inertial>
    <visual>
      <geometry>
        <mesh filename="objs/36.obj"/>
      </geometry>
      <origin xyz="0.0 0.0 0.0" rpy="0.0 -0.0 0.0"/>
    </visual>
  </link>
  <joint name="joint_revolute_99_36" type="prismatic">
    <limit effort="2000.0" velocity="2.0" lower="-0.0199964" upper="0.0"/>
    <parent link="l_99"/>
    <child link="l_36"/>
    <axis xyz="0 1 0"/>
    <origin xyz="0.0 0.0 -0.0" rpy="0.0 -0.0 0.0"/>
  </joint>
  <link name="l_37">
    <inertial>
      <origin xyz="0.0 0.0 0.0" rpy="0.0 -0.0 0.0"/>
      <mass value="0.043055400960000004"/>
      <inertia ixx="1.0" ixy="0.0" ixz="0.0" iyy="1.0" iyz="0.0" izz="1.0"/>
    </inertial>
    <visual>
      <geometry>
        <mesh filename="objs/37.obj"/>
      </geometry>
      <origin xyz="0.0 0.0 0.0" rpy="0.0 -0.0 0.0"/>
    </visual>
  </link>
  <joint name="joint_revolute_99_37" type="prismatic">
    <limit effort="2000.0" velocity="2.0" lower="-0.0199964" upper="0.0"/>
    <parent link="l_99"/>
    <child link="l_37"/>
    <axis xyz="0 1 0"/>
    <origin xyz="0.0 0.0 -0.0" rpy="0.0 -0.0 0.0"/>
  </joint>
  <link name="l_38">
    <inertial>
      <origin xyz="0.0 0.0 0.0" rpy="0.0 -0.0 0.0"/>
      <mass value="0.06936703488"/>
      <inertia ixx="1.0" ixy="0.0" ixz="0.0" iyy="1.0" iyz="0.0" izz="1.0"/>
    </inertial>
    <visual>
      <geometry>
        <mesh filename="objs/38.obj"/>
      </geometry>
      <origin xyz="0.0 0.0 0.0" rpy="0.0 -0.0 0.0"/>
    </visual>
  </link>
  <joint name="joint_revolute_99_38" type="prismatic">
    <limit effort="2000.0" velocity="2.0" lower="-0.0199964" upper="0.0"/>
    <parent link="l_99"/>
    <child link="l_38"/>
    <axis xyz="0 1 0"/>
    <origin xyz="0.0 0.0 -0.0" rpy="0.0 -0.0 0.0"/>
  </joint>
  <link name="l_39">
    <inertial>
      <origin xyz="0.0 0.0 0.0" rpy="0.0 -0.0 0.0"/>
      <mass value="0.0358795008"/>
      <inertia ixx="1.0" ixy="0.0" ixz="0.0" iyy="1.0" iyz="0.0" izz="1.0"/>
    </inertial>
    <visual>
      <geometry>
        <mesh filename="objs/39.obj"/>
      </geometry>
      <origin xyz="0.0 0.0 0.0" rpy="0.0 -0.0 0.0"/>
    </visual>
  </link>
  <joint name="joint_revolute_99_39" type="prismatic">
    <limit effort="2000.0" velocity="2.0" lower="-0.0199964" upper="0.0"/>
    <parent link="l_99"/>
    <child link="l_39"/>
    <axis xyz="0 1 0"/>
    <origin xyz="0.0 0.0 -0.0" rpy="0.0 -0.0 0.0"/>
  </joint>
  <link name="l_40">
    <inertial>
      <origin xyz="0.0 0.0 0.0" rpy="0.0 -0.0 0.0"/>
      <mass value="0.07893490176"/>
      <inertia ixx="1.0" ixy="0.0" ixz="0.0" iyy="1.0" iyz="0.0" izz="1.0"/>
    </inertial>
    <visual>
      <geometry>
        <mesh filename="objs/40.obj"/>
      </geometry>
      <origin xyz="0.0 0.0 0.0" rpy="0.0 -0.0 0.0"/>
    </visual>
  </link>
  <joint name="joint_revolute_99_40" type="prismatic">
    <limit effort="2000.0" velocity="2.0" lower="-0.0199964" upper="0.0"/>
    <parent link="l_99"/>
    <child link="l_40"/>
    <axis xyz="0 1 0"/>
    <origin xyz="0.0 0.0 -0.0" rpy="0.0 -0.0 0.0"/>
  </joint>
  <link name="l_41">
    <inertial>
      <origin xyz="0.0 0.0 0.0" rpy="0.0 -0.0 0.0"/>
      <mass value="0.045447367679999996"/>
      <inertia ixx="1.0" ixy="0.0" ixz="0.0" iyy="1.0" iyz="0.0" izz="1.0"/>
    </inertial>
    <visual>
      <geometry>
        <mesh filename="objs/41.obj"/>
      </geometry>
      <origin xyz="0.0 0.0 0.0" rpy="0.0 -0.0 0.0"/>
    </visual>
  </link>
  <joint name="joint_revolute_99_41" type="prismatic">
    <limit effort="2000.0" velocity="2.0" lower="-0.0199964" upper="0.0"/>
    <parent link="l_99"/>
    <child link="l_41"/>
    <axis xyz="0 1 0"/>
    <origin xyz="0.0 0.0 -0.0" rpy="0.0 -0.0 0.0"/>
  </joint>
  <link name="l_42">
    <inertial>
      <origin xyz="0.0 0.0 0.0" rpy="0.0 -0.0 0.0"/>
      <mass value="0.05501523456"/>
      <inertia ixx="1.0" ixy="0.0" ixz="0.0" iyy="1.0" iyz="0.0" izz="1.0"/>
    </inertial>
    <visual>
      <geometry>
        <mesh filename="objs/42.obj"/>
      </geometry>
      <origin xyz="0.0 0.0 0.0" rpy="0.0 -0.0 0.0"/>
    </visual>
  </link>
  <joint name="joint_revolute_99_42" type="prismatic">
    <limit effort="2000.0" velocity="2.0" lower="-0.0199964" upper="0.0"/>
    <parent link="l_99"/>
    <child link="l_42"/>
    <axis xyz="0 1 0"/>
    <origin xyz="0.0 0.0 -0.0" rpy="0.0 -0.0 0.0"/>
  </joint>
  <link name="l_43">
    <inertial>
      <origin xyz="0.0 0.0 0.0" rpy="0.0 -0.0 0.0"/>
      <mass value="0.02631163392"/>
      <inertia ixx="1.0" ixy="0.0" ixz="0.0" iyy="1.0" iyz="0.0" izz="1.0"/>
    </inertial>
    <visual>
      <geometry>
        <mesh filename="objs/43.obj"/>
      </geometry>
      <origin xyz="0.0 0.0 0.0" rpy="0.0 -0.0 0.0"/>
    </visual>
  </link>
  <joint name="joint_revolute_99_43" type="prismatic">
    <limit effort="2000.0" velocity="2.0" lower="-0.0199964" upper="0.0"/>
    <parent link="l_99"/>
    <child link="l_43"/>
    <axis xyz="0 1 0"/>
    <origin xyz="0.0 0.0 -0.0" rpy="0.0 -0.0 0.0"/>
  </joint>
  <link name="l_44">
    <inertial>
      <origin xyz="0.0 0.0 0.0" rpy="0.0 -0.0 0.0"/>
      <mass value="0.047839334399999996"/>
      <inertia ixx="1.0" ixy="0.0" ixz="0.0" iyy="1.0" iyz="0.0" izz="1.0"/>
    </inertial>
    <visual>
      <geometry>
        <mesh filename="objs/44.obj"/>
      </geometry>
      <origin xyz="0.0 0.0 0.0" rpy="0.0 -0.0 0.0"/>
    </visual>
  </link>
  <joint name="joint_revolute_99_44" type="prismatic">
    <limit effort="2000.0" velocity="2.0" lower="-0.0199964" upper="0.0"/>
    <parent link="l_99"/>
    <child link="l_44"/>
    <axis xyz="0 1 0"/>
    <origin xyz="0.0 0.0 -0.0" rpy="0.0 -0.0 0.0"/>
  </joint>
  <link name="l_45">
    <inertial>
      <origin xyz="0.0 0.0 0.0" rpy="0.0 -0.0 0.0"/>
      <mass value="0.059799168"/>
      <inertia ixx="1.0" ixy="0.0" ixz="0.0" iyy="1.0" iyz="0.0" izz="1.0"/>
    </inertial>
    <visual>
      <geometry>
        <mesh filename="objs/45.obj"/>
      </geometry>
      <origin xyz="0.0 0.0 0.0" rpy="0.0 -0.0 0.0"/>
    </visual>
  </link>
  <joint name="joint_revolute_99_45" type="prismatic">
    <limit effort="2000.0" velocity="2.0" lower="-0.0199964" upper="0.0"/>
    <parent link="l_99"/>
    <child link="l_45"/>
    <axis xyz="0 1 0"/>
    <origin xyz="0.0 0.0 -0.0" rpy="0.0 -0.0 0.0"/>
  </joint>
  <link name="l_46">
    <inertial>
      <origin xyz="0.0 0.0 0.0" rpy="0.0 -0.0 0.0"/>
      <mass value="0.05262326784"/>
      <inertia ixx="1.0" ixy="0.0" ixz="0.0" iyy="1.0" iyz="0.0" izz="1.0"/>
    </inertial>
    <visual>
      <geometry>
        <mesh filename="objs/46.obj"/>
      </geometry>
      <origin xyz="0.0 0.0 0.0" rpy="0.0 -0.0 0.0"/>
    </visual>
  </link>
  <joint name="joint_revolute_99_46" type="prismatic">
    <limit effort="2000.0" velocity="2.0" lower="-0.0199964" upper="0.0"/>
    <parent link="l_99"/>
    <child link="l_46"/>
    <axis xyz="0 1 0"/>
    <origin xyz="0.0 0.0 -0.0" rpy="0.0 -0.0 0.0"/>
  </joint>
  <link name="l_47">
    <inertial>
      <origin xyz="0.0 0.0 0.0" rpy="0.0 -0.0 0.0"/>
      <mass value="0.06697506815999998"/>
      <inertia ixx="1.0" ixy="0.0" ixz="0.0" iyy="1.0" iyz="0.0" izz="1.0"/>
    </inertial>
    <visual>
      <geometry>
        <mesh filename="objs/47.obj"/>
      </geometry>
      <origin xyz="0.0 0.0 0.0" rpy="0.0 -0.0 0.0"/>
    </visual>
  </link>
  <joint name="joint_revolute_99_47" type="prismatic">
    <limit effort="2000.0" velocity="2.0" lower="-0.0199964" upper="0.0"/>
    <parent link="l_99"/>
    <child link="l_47"/>
    <axis xyz="0 1 0"/>
    <origin xyz="0.0 0.0 -0.0" rpy="0.0 -0.0 0.0"/>
  </joint>
  <link name="l_48">
    <inertial>
      <origin xyz="0.0 0.0 0.0" rpy="0.0 -0.0 0.0"/>
      <mass value="0.0717590016"/>
      <inertia ixx="1.0" ixy="0.0" ixz="0.0" iyy="1.0" iyz="0.0" izz="1.0"/>
    </inertial>
    <visual>
      <geometry>
        <mesh filename="objs/48.obj"/>
      </geometry>
      <origin xyz="0.0 0.0 0.0" rpy="0.0 -0.0 0.0"/>
    </visual>
  </link>
  <joint name="joint_revolute_99_48" type="prismatic">
    <limit effort="2000.0" velocity="2.0" lower="-0.0199964" upper="0.0"/>
    <parent link="l_99"/>
    <child link="l_48"/>
    <axis xyz="0 1 0"/>
    <origin xyz="0.0 0.0 -0.0" rpy="0.0 -0.0 0.0"/>
  </joint>
  <link name="l_49">
    <inertial>
      <origin xyz="0.0 0.0 0.0" rpy="0.0 -0.0 0.0"/>
      <mass value="0.05262326784"/>
      <inertia ixx="1.0" ixy="0.0" ixz="0.0" iyy="1.0" iyz="0.0" izz="1.0"/>
    </inertial>
    <visual>
      <geometry>
        <mesh filename="objs/49.obj"/>
      </geometry>
      <origin xyz="0.0 0.0 0.0" rpy="0.0 -0.0 0.0"/>
    </visual>
  </link>
  <joint name="joint_revolute_99_49" type="prismatic">
    <limit effort="2000.0" velocity="2.0" lower="-0.0199964" upper="0.0"/>
    <parent link="l_99"/>
    <child link="l_49"/>
    <axis xyz="0 1 0"/>
    <origin xyz="0.0 0.0 -0.0" rpy="0.0 -0.0 0.0"/>
  </joint>
  <link name="l_50">
    <inertial>
      <origin xyz="0.0 0.0 0.0" rpy="0.0 -0.0 0.0"/>
      <mass value="0.06697506815999998"/>
      <inertia ixx="1.0" ixy="0.0" ixz="0.0" iyy="1.0" iyz="0.0" izz="1.0"/>
    </inertial>
    <visual>
      <geometry>
        <mesh filename="objs/50.obj"/>
      </geometry>
      <origin xyz="0.0 0.0 0.0" rpy="0.0 -0.0 0.0"/>
    </visual>
  </link>
  <joint name="joint_revolute_99_50" type="prismatic">
    <limit effort="2000.0" velocity="2.0" lower="-0.0199964" upper="0.0"/>
    <parent link="l_99"/>
    <child link="l_50"/>
    <axis xyz="0 1 0"/>
    <origin xyz="0.0 0.0 -0.0" rpy="0.0 -0.0 0.0"/>
  </joint>
  <link name="l_51">
    <inertial>
      <origin xyz="0.0 0.0 0.0" rpy="0.0 -0.0 0.0"/>
      <mass value="0.05262326784"/>
      <inertia ixx="1.0" ixy="0.0" ixz="0.0" iyy="1.0" iyz="0.0" izz="1.0"/>
    </inertial>
    <visual>
      <geometry>
        <mesh filename="objs/51.obj"/>
      </geometry>
      <origin xyz="0.0 0.0 0.0" rpy="0.0 -0.0 0.0"/>
    </visual>
  </link>
  <joint name="joint_revolute_99_51" type="prismatic">
    <limit effort="2000.0" velocity="2.0" lower="-0.0199964" upper="0.0"/>
    <parent link="l_99"/>
    <child link="l_51"/>
    <axis xyz="0 1 0"/>
    <origin xyz="0.0 0.0 -0.0" rpy="0.0 -0.0 0.0"/>
  </joint>
  <link name="l_52">
    <inertial>
      <origin xyz="0.0 0.0 0.0" rpy="0.0 -0.0 0.0"/>
      <mass value="0.06697506815999998"/>
      <inertia ixx="1.0" ixy="0.0" ixz="0.0" iyy="1.0" iyz="0.0" izz="1.0"/>
    </inertial>
    <visual>
      <geometry>
        <mesh filename="objs/52.obj"/>
      </geometry>
      <origin xyz="0.0 0.0 0.0" rpy="0.0 -0.0 0.0"/>
    </visual>
  </link>
  <joint name="joint_revolute_99_52" type="prismatic">
    <limit effort="2000.0" velocity="2.0" lower="-0.0199964" upper="0.0"/>
    <parent link="l_99"/>
    <child link="l_52"/>
    <axis xyz="0 1 0"/>
    <origin xyz="0.0 0.0 -0.0" rpy="0.0 -0.0 0.0"/>
  </joint>
  <link name="l_53">
    <inertial>
      <origin xyz="0.0 0.0 0.0" rpy="0.0 -0.0 0.0"/>
      <mass value="0.05501523456"/>
      <inertia ixx="1.0" ixy="0.0" ixz="0.0" iyy="1.0" iyz="0.0" izz="1.0"/>
    </inertial>
    <visual>
      <geometry>
        <mesh filename="objs/53.obj"/>
      </geometry>
      <origin xyz="0.0 0.0 0.0" rpy="0.0 -0.0 0.0"/>
    </visual>
  </link>
  <joint name="joint_revolute_99_53" type="prismatic">
    <limit effort="2000.0" velocity="2.0" lower="-0.0199964" upper="0.0"/>
    <parent link="l_99"/>
    <child link="l_53"/>
    <axis xyz="0 1 0"/>
    <origin xyz="0.0 0.0 -0.0" rpy="0.0 -0.0 0.0"/>
  </joint>
  <link name="l_54">
    <inertial>
      <origin xyz="0.0 0.0 0.0" rpy="0.0 -0.0 0.0"/>
      <mass value="0.050231301119999995"/>
      <inertia ixx="1.0" ixy="0.0" ixz="0.0" iyy="1.0" iyz="0.0" izz="1.0"/>
    </inertial>
    <visual>
      <geometry>
        <mesh filename="objs/54.obj"/>
      </geometry>
      <origin xyz="0.0 0.0 0.0" rpy="0.0 -0.0 0.0"/>
    </visual>
  </link>
  <joint name="joint_revolute_99_54" type="prismatic">
    <limit effort="2000.0" velocity="2.0" lower="-0.0199964" upper="0.0"/>
    <parent link="l_99"/>
    <child link="l_54"/>
    <axis xyz="0 1 0"/>
    <origin xyz="0.0 0.0 -0.0" rpy="0.0 -0.0 0.0"/>
  </joint>
  <link name="l_55">
    <inertial>
      <origin xyz="0.0 0.0 0.0" rpy="0.0 -0.0 0.0"/>
      <mass value="0.05501523456"/>
      <inertia ixx="1.0" ixy="0.0" ixz="0.0" iyy="1.0" iyz="0.0" izz="1.0"/>
    </inertial>
    <visual>
      <geometry>
        <mesh filename="objs/55.obj"/>
      </geometry>
      <origin xyz="0.0 0.0 0.0" rpy="0.0 -0.0 0.0"/>
    </visual>
  </link>
  <joint name="joint_revolute_99_55" type="prismatic">
    <limit effort="2000.0" velocity="2.0" lower="-0.0199964" upper="0.0"/>
    <parent link="l_99"/>
    <child link="l_55"/>
    <axis xyz="0 1 0"/>
    <origin xyz="0.0 0.0 -0.0" rpy="0.0 -0.0 0.0"/>
  </joint>
  <link name="l_56">
    <inertial>
      <origin xyz="0.0 0.0 0.0" rpy="0.0 -0.0 0.0"/>
      <mass value="0.06219113472"/>
      <inertia ixx="1.0" ixy="0.0" ixz="0.0" iyy="1.0" iyz="0.0" izz="1.0"/>
    </inertial>
    <visual>
      <geometry>
        <mesh filename="objs/56.obj"/>
      </geometry>
      <origin xyz="0.0 0.0 0.0" rpy="0.0 -0.0 0.0"/>
    </visual>
  </link>
  <joint name="joint_revolute_99_56" type="prismatic">
    <limit effort="2000.0" velocity="2.0" lower="-0.0199964" upper="0.0"/>
    <parent link="l_99"/>
    <child link="l_56"/>
    <axis xyz="0 1 0"/>
    <origin xyz="0.0 0.0 -0.0" rpy="0.0 -0.0 0.0"/>
  </joint>
  <link name="l_57">
    <inertial>
      <origin xyz="0.0 0.0 0.0" rpy="0.0 -0.0 0.0"/>
      <mass value="0.047839334399999996"/>
      <inertia ixx="1.0" ixy="0.0" ixz="0.0" iyy="1.0" iyz="0.0" izz="1.0"/>
    </inertial>
    <visual>
      <geometry>
        <mesh filename="objs/57.obj"/>
      </geometry>
      <origin xyz="0.0 0.0 0.0" rpy="0.0 -0.0 0.0"/>
    </visual>
  </link>
  <joint name="joint_revolute_99_57" type="prismatic">
    <limit effort="2000.0" velocity="2.0" lower="-0.0199964" upper="0.0"/>
    <parent link="l_99"/>
    <child link="l_57"/>
    <axis xyz="0 1 0"/>
    <origin xyz="0.0 0.0 -0.0" rpy="0.0 -0.0 0.0"/>
  </joint>
  <link name="l_58">
    <inertial>
      <origin xyz="0.0 0.0 0.0" rpy="0.0 -0.0 0.0"/>
      <mass value="0.043055400960000004"/>
      <inertia ixx="1.0" ixy="0.0" ixz="0.0" iyy="1.0" iyz="0.0" izz="1.0"/>
    </inertial>
    <visual>
      <geometry>
        <mesh filename="objs/58.obj"/>
      </geometry>
      <origin xyz="0.0 0.0 0.0" rpy="0.0 -0.0 0.0"/>
    </visual>
  </link>
  <joint name="joint_revolute_99_58" type="prismatic">
    <limit effort="2000.0" velocity="2.0" lower="-0.0199964" upper="0.0"/>
    <parent link="l_99"/>
    <child link="l_58"/>
    <axis xyz="0 1 0"/>
    <origin xyz="0.0 0.0 -0.0" rpy="0.0 -0.0 0.0"/>
  </joint>
  <link name="l_59">
    <inertial>
      <origin xyz="0.0 0.0 0.0" rpy="0.0 -0.0 0.0"/>
      <mass value="0.05501523456"/>
      <inertia ixx="1.0" ixy="0.0" ixz="0.0" iyy="1.0" iyz="0.0" izz="1.0"/>
    </inertial>
    <visual>
      <geometry>
        <mesh filename="objs/59.obj"/>
      </geometry>
      <origin xyz="0.0 0.0 0.0" rpy="0.0 -0.0 0.0"/>
    </visual>
  </link>
  <joint name="joint_revolute_99_59" type="prismatic">
    <limit effort="2000.0" velocity="2.0" lower="-0.0199964" upper="0.0"/>
    <parent link="l_99"/>
    <child link="l_59"/>
    <axis xyz="0 1 0"/>
    <origin xyz="0.0 0.0 -0.0" rpy="0.0 -0.0 0.0"/>
  </joint>
  <link name="l_60">
    <inertial>
      <origin xyz="0.0 0.0 0.0" rpy="0.0 -0.0 0.0"/>
      <mass value="0.047839334399999996"/>
      <inertia ixx="1.0" ixy="0.0" ixz="0.0" iyy="1.0" iyz="0.0" izz="1.0"/>
    </inertial>
    <visual>
      <geometry>
        <mesh filename="objs/60.obj"/>
      </geometry>
      <origin xyz="0.0 0.0 0.0" rpy="0.0 -0.0 0.0"/>
    </visual>
  </link>
  <joint name="joint_revolute_99_60" type="prismatic">
    <limit effort="2000.0" velocity="2.0" lower="-0.0199964" upper="0.0"/>
    <parent link="l_99"/>
    <child link="l_60"/>
    <axis xyz="0 1 0"/>
    <origin xyz="0.0 0.0 -0.0" rpy="0.0 -0.0 0.0"/>
  </joint>
  <link name="l_61">
    <inertial>
      <origin xyz="0.0 0.0 0.0" rpy="0.0 -0.0 0.0"/>
      <mass value="0.07893490176"/>
      <inertia ixx="1.0" ixy="0.0" ixz="0.0" iyy="1.0" iyz="0.0" izz="1.0"/>
    </inertial>
    <visual>
      <geometry>
        <mesh filename="objs/61.obj"/>
      </geometry>
      <origin xyz="0.0 0.0 0.0" rpy="0.0 -0.0 0.0"/>
    </visual>
  </link>
  <joint name="joint_revolute_99_61" type="prismatic">
    <limit effort="2000.0" velocity="2.0" lower="-0.0199964" upper="0.0"/>
    <parent link="l_99"/>
    <child link="l_61"/>
    <axis xyz="0 1 0"/>
    <origin xyz="0.0 0.0 -0.0" rpy="0.0 -0.0 0.0"/>
  </joint>
  <link name="l_62">
    <inertial>
      <origin xyz="0.0 0.0 0.0" rpy="0.0 -0.0 0.0"/>
      <mass value="0.19853323775999998"/>
      <inertia ixx="1.0" ixy="0.0" ixz="0.0" iyy="1.0" iyz="0.0" izz="1.0"/>
    </inertial>
    <visual>
      <geometry>
        <mesh filename="objs/62.obj"/>
      </geometry>
      <origin xyz="0.0 0.0 0.0" rpy="0.0 -0.0 0.0"/>
    </visual>
  </link>
  <joint name="joint_revolute_99_62" type="prismatic">
    <limit effort="2000.0" velocity="2.0" lower="-0.0199964" upper="0.0"/>
    <parent link="l_99"/>
    <child link="l_62"/>
    <axis xyz="0 1 0"/>
    <origin xyz="0.0 0.0 -0.0" rpy="0.0 -0.0 0.0"/>
  </joint>
  <link name="l_63">
    <inertial>
      <origin xyz="0.0 0.0 0.0" rpy="0.0 -0.0 0.0"/>
      <mass value="0.047839334399999996"/>
      <inertia ixx="1.0" ixy="0.0" ixz="0.0" iyy="1.0" iyz="0.0" izz="1.0"/>
    </inertial>
    <visual>
      <geometry>
        <mesh filename="objs/63.obj"/>
      </geometry>
      <origin xyz="0.0 0.0 0.0" rpy="0.0 -0.0 0.0"/>
    </visual>
  </link>
  <joint name="joint_revolute_99_63" type="prismatic">
    <limit effort="2000.0" velocity="2.0" lower="-0.0199964" upper="0.0"/>
    <parent link="l_99"/>
    <child link="l_63"/>
    <axis xyz="0 1 0"/>
    <origin xyz="0.0 0.0 -0.0" rpy="0.0 -0.0 0.0"/>
  </joint>
  <link name="l_64">
    <inertial>
      <origin xyz="0.0 0.0 0.0" rpy="0.0 -0.0 0.0"/>
      <mass value="0.05501523456"/>
      <inertia ixx="1.0" ixy="0.0" ixz="0.0" iyy="1.0" iyz="0.0" izz="1.0"/>
    </inertial>
    <visual>
      <geometry>
        <mesh filename="objs/64.obj"/>
      </geometry>
      <origin xyz="0.0 0.0 0.0" rpy="0.0 -0.0 0.0"/>
    </visual>
  </link>
  <joint name="joint_revolute_99_64" type="prismatic">
    <limit effort="2000.0" velocity="2.0" lower="-0.0199964" upper="0.0"/>
    <parent link="l_99"/>
    <child link="l_64"/>
    <axis xyz="0 1 0"/>
    <origin xyz="0.0 0.0 -0.0" rpy="0.0 -0.0 0.0"/>
  </joint>
  <link name="l_65">
    <inertial>
      <origin xyz="0.0 0.0 0.0" rpy="0.0 -0.0 0.0"/>
      <mass value="0.06458310144"/>
      <inertia ixx="1.0" ixy="0.0" ixz="0.0" iyy="1.0" iyz="0.0" izz="1.0"/>
    </inertial>
    <visual>
      <geometry>
        <mesh filename="objs/65.obj"/>
      </geometry>
      <origin xyz="0.0 0.0 0.0" rpy="0.0 -0.0 0.0"/>
    </visual>
  </link>
  <joint name="joint_revolute_99_65" type="prismatic">
    <limit effort="2000.0" velocity="2.0" lower="-0.0199964" upper="0.0"/>
    <parent link="l_99"/>
    <child link="l_65"/>
    <axis xyz="0 1 0"/>
    <origin xyz="0.0 0.0 -0.0" rpy="0.0 -0.0 0.0"/>
  </joint>
  <link name="l_66">
    <inertial>
      <origin xyz="0.0 0.0 0.0" rpy="0.0 -0.0 0.0"/>
      <mass value="0.05262326784"/>
      <inertia ixx="1.0" ixy="0.0" ixz="0.0" iyy="1.0" iyz="0.0" izz="1.0"/>
    </inertial>
    <visual>
      <geometry>
        <mesh filename="objs/66.obj"/>
      </geometry>
      <origin xyz="0.0 0.0 0.0" rpy="0.0 -0.0 0.0"/>
    </visual>
  </link>
  <joint name="joint_revolute_99_66" type="prismatic">
    <limit effort="2000.0" velocity="2.0" lower="-0.0199964" upper="0.0"/>
    <parent link="l_99"/>
    <child link="l_66"/>
    <axis xyz="0 1 0"/>
    <origin xyz="0.0 0.0 -0.0" rpy="0.0 -0.0 0.0"/>
  </joint>
  <link name="l_67">
    <inertial>
      <origin xyz="0.0 0.0 0.0" rpy="0.0 -0.0 0.0"/>
      <mass value="0.03827146752"/>
      <inertia ixx="1.0" ixy="0.0" ixz="0.0" iyy="1.0" iyz="0.0" izz="1.0"/>
    </inertial>
    <visual>
      <geometry>
        <mesh filename="objs/67.obj"/>
      </geometry>
      <origin xyz="0.0 0.0 0.0" rpy="0.0 -0.0 0.0"/>
    </visual>
  </link>
  <joint name="joint_revolute_99_67" type="prismatic">
    <limit effort="2000.0" velocity="2.0" lower="-0.0199964" upper="0.0"/>
    <parent link="l_99"/>
    <child link="l_67"/>
    <axis xyz="0 1 0"/>
    <origin xyz="0.0 0.0 -0.0" rpy="0.0 -0.0 0.0"/>
  </joint>
  <link name="l_68">
    <inertial>
      <origin xyz="0.0 0.0 0.0" rpy="0.0 -0.0 0.0"/>
      <mass value="0.05262326784"/>
      <inertia ixx="1.0" ixy="0.0" ixz="0.0" iyy="1.0" iyz="0.0" izz="1.0"/>
    </inertial>
    <visual>
      <geometry>
        <mesh filename="objs/68.obj"/>
      </geometry>
      <origin xyz="0.0 0.0 0.0" rpy="0.0 -0.0 0.0"/>
    </visual>
  </link>
  <joint name="joint_revolute_99_68" type="prismatic">
    <limit effort="2000.0" velocity="2.0" lower="-0.0199964" upper="0.0"/>
    <parent link="l_99"/>
    <child link="l_68"/>
    <axis xyz="0 1 0"/>
    <origin xyz="0.0 0.0 -0.0" rpy="0.0 -0.0 0.0"/>
  </joint>
  <link name="l_69">
    <inertial>
      <origin xyz="0.0 0.0 0.0" rpy="0.0 -0.0 0.0"/>
      <mass value="0.050231301119999995"/>
      <inertia ixx="1.0" ixy="0.0" ixz="0.0" iyy="1.0" iyz="0.0" izz="1.0"/>
    </inertial>
    <visual>
      <geometry>
        <mesh filename="objs/69.obj"/>
      </geometry>
      <origin xyz="0.0 0.0 0.0" rpy="0.0 -0.0 0.0"/>
    </visual>
  </link>
  <joint name="joint_revolute_99_69" type="prismatic">
    <limit effort="2000.0" velocity="2.0" lower="-0.0199964" upper="0.0"/>
    <parent link="l_99"/>
    <child link="l_69"/>
    <axis xyz="0 1 0"/>
    <origin xyz="0.0 0.0 -0.0" rpy="0.0 -0.0 0.0"/>
  </joint>
  <link name="l_70">
    <inertial>
      <origin xyz="0.0 0.0 0.0" rpy="0.0 -0.0 0.0"/>
      <mass value="0.050231301119999995"/>
      <inertia ixx="1.0" ixy="0.0" ixz="0.0" iyy="1.0" iyz="0.0" izz="1.0"/>
    </inertial>
    <visual>
      <geometry>
        <mesh filename="objs/70.obj"/>
      </geometry>
      <origin xyz="0.0 0.0 0.0" rpy="0.0 -0.0 0.0"/>
    </visual>
  </link>
  <joint name="joint_revolute_99_70" type="prismatic">
    <limit effort="2000.0" velocity="2.0" lower="-0.0199964" upper="0.0"/>
    <parent link="l_99"/>
    <child link="l_70"/>
    <axis xyz="0 1 0"/>
    <origin xyz="0.0 0.0 -0.0" rpy="0.0 -0.0 0.0"/>
  </joint>
  <link name="l_71">
    <inertial>
      <origin xyz="0.0 0.0 0.0" rpy="0.0 -0.0 0.0"/>
      <mass value="0.05501523456"/>
      <inertia ixx="1.0" ixy="0.0" ixz="0.0" iyy="1.0" iyz="0.0" izz="1.0"/>
    </inertial>
    <visual>
      <geometry>
        <mesh filename="objs/71.obj"/>
      </geometry>
      <origin xyz="0.0 0.0 0.0" rpy="0.0 -0.0 0.0"/>
    </visual>
  </link>
  <joint name="joint_revolute_99_71" type="prismatic">
    <limit effort="2000.0" velocity="2.0" lower="-0.0199964" upper="0.0"/>
    <parent link="l_99"/>
    <child link="l_71"/>
    <axis xyz="0 1 0"/>
    <origin xyz="0.0 0.0 -0.0" rpy="0.0 -0.0 0.0"/>
  </joint>
  <link name="l_72">
    <inertial>
      <origin xyz="0.0 0.0 0.0" rpy="0.0 -0.0 0.0"/>
      <mass value="0.040663434240000004"/>
      <inertia ixx="1.0" ixy="0.0" ixz="0.0" iyy="1.0" iyz="0.0" izz="1.0"/>
    </inertial>
    <visual>
      <geometry>
        <mesh filename="objs/72.obj"/>
      </geometry>
      <origin xyz="0.0 0.0 0.0" rpy="0.0 -0.0 0.0"/>
    </visual>
  </link>
  <joint name="joint_revolute_99_72" type="prismatic">
    <limit effort="2000.0" velocity="2.0" lower="-0.0199964" upper="0.0"/>
    <parent link="l_99"/>
    <child link="l_72"/>
    <axis xyz="0 1 0"/>
    <origin xyz="0.0 0.0 -0.0" rpy="0.0 -0.0 0.0"/>
  </joint>
  <link name="l_73">
    <inertial>
      <origin xyz="0.0 0.0 0.0" rpy="0.0 -0.0 0.0"/>
      <mass value="0.03827146752"/>
      <inertia ixx="1.0" ixy="0.0" ixz="0.0" iyy="1.0" iyz="0.0" izz="1.0"/>
    </inertial>
    <visual>
      <geometry>
        <mesh filename="objs/73.obj"/>
      </geometry>
      <origin xyz="0.0 0.0 0.0" rpy="0.0 -0.0 0.0"/>
    </visual>
  </link>
  <joint name="joint_revolute_99_73" type="prismatic">
    <limit effort="2000.0" velocity="2.0" lower="-0.0199964" upper="0.0"/>
    <parent link="l_99"/>
    <child link="l_73"/>
    <axis xyz="0 1 0"/>
    <origin xyz="0.0 0.0 -0.0" rpy="0.0 -0.0 0.0"/>
  </joint>
  <link name="l_74">
    <inertial>
      <origin xyz="0.0 0.0 0.0" rpy="0.0 -0.0 0.0"/>
      <mass value="0.05501523456"/>
      <inertia ixx="1.0" ixy="0.0" ixz="0.0" iyy="1.0" iyz="0.0" izz="1.0"/>
    </inertial>
    <visual>
      <geometry>
        <mesh filename="objs/74.obj"/>
      </geometry>
      <origin xyz="0.0 0.0 0.0" rpy="0.0 -0.0 0.0"/>
    </visual>
  </link>
  <joint name="joint_revolute_99_74" type="prismatic">
    <limit effort="2000.0" velocity="2.0" lower="-0.0199964" upper="0.0"/>
    <parent link="l_99"/>
    <child link="l_74"/>
    <axis xyz="0 1 0"/>
    <origin xyz="0.0 0.0 -0.0" rpy="0.0 -0.0 0.0"/>
  </joint>
  <link name="l_75">
    <inertial>
      <origin xyz="0.0 0.0 0.0" rpy="0.0 -0.0 0.0"/>
      <mass value="0.07415096832"/>
      <inertia ixx="1.0" ixy="0.0" ixz="0.0" iyy="1.0" iyz="0.0" izz="1.0"/>
    </inertial>
    <visual>
      <geometry>
        <mesh filename="objs/75.obj"/>
      </geometry>
      <origin xyz="0.0 0.0 0.0" rpy="0.0 -0.0 0.0"/>
    </visual>
  </link>
  <joint name="joint_revolute_99_75" type="prismatic">
    <limit effort="2000.0" velocity="2.0" lower="-0.0199964" upper="0.0"/>
    <parent link="l_99"/>
    <child link="l_75"/>
    <axis xyz="0 1 0"/>
    <origin xyz="0.0 0.0 -0.0" rpy="0.0 -0.0 0.0"/>
  </joint>
  <link name="l_76">
    <inertial>
      <origin xyz="0.0 0.0 0.0" rpy="0.0 -0.0 0.0"/>
      <mass value="0.045447367679999996"/>
      <inertia ixx="1.0" ixy="0.0" ixz="0.0" iyy="1.0" iyz="0.0" izz="1.0"/>
    </inertial>
    <visual>
      <geometry>
        <mesh filename="objs/76.obj"/>
      </geometry>
      <origin xyz="0.0 0.0 0.0" rpy="0.0 -0.0 0.0"/>
    </visual>
  </link>
  <joint name="joint_revolute_99_76" type="prismatic">
    <limit effort="2000.0" velocity="2.0" lower="-0.0199964" upper="0.0"/>
    <parent link="l_99"/>
    <child link="l_76"/>
    <axis xyz="0 1 0"/>
    <origin xyz="0.0 0.0 -0.0" rpy="0.0 -0.0 0.0"/>
  </joint>
  <link name="l_77">
    <inertial>
      <origin xyz="0.0 0.0 0.0" rpy="0.0 -0.0 0.0"/>
      <mass value="0.050231301119999995"/>
      <inertia ixx="1.0" ixy="0.0" ixz="0.0" iyy="1.0" iyz="0.0" izz="1.0"/>
    </inertial>
    <visual>
      <geometry>
        <mesh filename="objs/77.obj"/>
      </geometry>
      <origin xyz="0.0 0.0 0.0" rpy="0.0 -0.0 0.0"/>
    </visual>
  </link>
  <joint name="joint_revolute_99_77" type="prismatic">
    <limit effort="2000.0" velocity="2.0" lower="-0.0199964" upper="0.0"/>
    <parent link="l_99"/>
    <child link="l_77"/>
    <axis xyz="0 1 0"/>
    <origin xyz="0.0 0.0 -0.0" rpy="0.0 -0.0 0.0"/>
  </joint>
  <link name="l_78">
    <inertial>
      <origin xyz="0.0 0.0 0.0" rpy="0.0 -0.0 0.0"/>
      <mass value="0.05501523456"/>
      <inertia ixx="1.0" ixy="0.0" ixz="0.0" iyy="1.0" iyz="0.0" izz="1.0"/>
    </inertial>
    <visual>
      <geometry>
        <mesh filename="objs/78.obj"/>
      </geometry>
      <origin xyz="0.0 0.0 0.0" rpy="0.0 -0.0 0.0"/>
    </visual>
  </link>
  <joint name="joint_revolute_99_78" type="prismatic">
    <limit effort="2000.0" velocity="2.0" lower="-0.0199964" upper="0.0"/>
    <parent link="l_99"/>
    <child link="l_78"/>
    <axis xyz="0 1 0"/>
    <origin xyz="0.0 0.0 -0.0" rpy="0.0 -0.0 0.0"/>
  </joint>
  <link name="l_79">
    <inertial>
      <origin xyz="0.0 0.0 0.0" rpy="0.0 -0.0 0.0"/>
      <mass value="0.07893490176"/>
      <inertia ixx="1.0" ixy="0.0" ixz="0.0" iyy="1.0" iyz="0.0" izz="1.0"/>
    </inertial>
    <visual>
      <geometry>
        <mesh filename="objs/79.obj"/>
      </geometry>
      <origin xyz="0.0 0.0 0.0" rpy="0.0 -0.0 0.0"/>
    </visual>
  </link>
  <joint name="joint_revolute_99_79" type="prismatic">
    <limit effort="2000.0" velocity="2.0" lower="-0.0199964" upper="0.0"/>
    <parent link="l_99"/>
    <child link="l_79"/>
    <axis xyz="0 1 0"/>
    <origin xyz="0.0 0.0 -0.0" rpy="0.0 -0.0 0.0"/>
  </joint>
  <link name="l_80">
    <inertial>
      <origin xyz="0.0 0.0 0.0" rpy="0.0 -0.0 0.0"/>
      <mass value="0.047839334399999996"/>
      <inertia ixx="1.0" ixy="0.0" ixz="0.0" iyy="1.0" iyz="0.0" izz="1.0"/>
    </inertial>
    <visual>
      <geometry>
        <mesh filename="objs/80.obj"/>
      </geometry>
      <origin xyz="0.0 0.0 0.0" rpy="0.0 -0.0 0.0"/>
    </visual>
  </link>
  <joint name="joint_revolute_99_80" type="prismatic">
    <limit effort="2000.0" velocity="2.0" lower="-0.0199964" upper="0.0"/>
    <parent link="l_99"/>
    <child link="l_80"/>
    <axis xyz="0 1 0"/>
    <origin xyz="0.0 0.0 -0.0" rpy="0.0 -0.0 0.0"/>
  </joint>
  <link name="l_81">
    <inertial>
      <origin xyz="0.0 0.0 0.0" rpy="0.0 -0.0 0.0"/>
      <mass value="0.045447367679999996"/>
      <inertia ixx="1.0" ixy="0.0" ixz="0.0" iyy="1.0" iyz="0.0" izz="1.0"/>
    </inertial>
    <visual>
      <geometry>
        <mesh filename="objs/81.obj"/>
      </geometry>
      <origin xyz="0.0 0.0 0.0" rpy="0.0 -0.0 0.0"/>
    </visual>
  </link>
  <joint name="joint_revolute_99_81" type="prismatic">
    <limit effort="2000.0" velocity="2.0" lower="-0.0199964" upper="0.0"/>
    <parent link="l_99"/>
    <child link="l_81"/>
    <axis xyz="0 1 0"/>
    <origin xyz="0.0 0.0 -0.0" rpy="0.0 -0.0 0.0"/>
  </joint>
  <link name="l_82">
    <inertial>
      <origin xyz="0.0 0.0 0.0" rpy="0.0 -0.0 0.0"/>
      <mass value="0.05501523456"/>
      <inertia ixx="1.0" ixy="0.0" ixz="0.0" iyy="1.0" iyz="0.0" izz="1.0"/>
    </inertial>
    <visual>
      <geometry>
        <mesh filename="objs/82.obj"/>
      </geometry>
      <origin xyz="0.0 0.0 0.0" rpy="0.0 -0.0 0.0"/>
    </visual>
  </link>
  <joint name="joint_revolute_99_82" type="prismatic">
    <limit effort="2000.0" velocity="2.0" lower="-0.0199964" upper="0.0"/>
    <parent link="l_99"/>
    <child link="l_82"/>
    <axis xyz="0 1 0"/>
    <origin xyz="0.0 0.0 -0.0" rpy="0.0 -0.0 0.0"/>
  </joint>
  <link name="l_83">
    <inertial>
      <origin xyz="0.0 0.0 0.0" rpy="0.0 -0.0 0.0"/>
      <mass value="0.047839334399999996"/>
      <inertia ixx="1.0" ixy="0.0" ixz="0.0" iyy="1.0" iyz="0.0" izz="1.0"/>
    </inertial>
    <visual>
      <geometry>
        <mesh filename="objs/83.obj"/>
      </geometry>
      <origin xyz="0.0 0.0 0.0" rpy="0.0 -0.0 0.0"/>
    </visual>
  </link>
  <joint name="joint_revolute_99_83" type="prismatic">
    <limit effort="2000.0" velocity="2.0" lower="-0.0199964" upper="0.0"/>
    <parent link="l_99"/>
    <child link="l_83"/>
    <axis xyz="0 1 0"/>
    <origin xyz="0.0 0.0 -0.0" rpy="0.0 -0.0 0.0"/>
  </joint>
  <link name="l_84">
    <inertial>
      <origin xyz="0.0 0.0 0.0" rpy="0.0 -0.0 0.0"/>
      <mass value="0.03827146752"/>
      <inertia ixx="1.0" ixy="0.0" ixz="0.0" iyy="1.0" iyz="0.0" izz="1.0"/>
    </inertial>
    <visual>
      <geometry>
        <mesh filename="objs/84.obj"/>
      </geometry>
      <origin xyz="0.0 0.0 0.0" rpy="0.0 -0.0 0.0"/>
    </visual>
  </link>
  <joint name="joint_revolute_99_84" type="prismatic">
    <limit effort="2000.0" velocity="2.0" lower="-0.0199964" upper="0.0"/>
    <parent link="l_99"/>
    <child link="l_84"/>
    <axis xyz="0 1 0"/>
    <origin xyz="0.0 0.0 -0.0" rpy="0.0 -0.0 0.0"/>
  </joint>
  <link name="l_85">
    <inertial>
      <origin xyz="0.0 0.0 0.0" rpy="0.0 -0.0 0.0"/>
      <mass value="0.05740720128"/>
      <inertia ixx="1.0" ixy="0.0" ixz="0.0" iyy="1.0" iyz="0.0" izz="1.0"/>
    </inertial>
    <visual>
      <geometry>
        <mesh filename="objs/85.obj"/>
      </geometry>
      <origin xyz="0.0 0.0 0.0" rpy="0.0 -0.0 0.0"/>
    </visual>
  </link>
  <joint name="joint_revolute_99_85" type="prismatic">
    <limit effort="2000.0" velocity="2.0" lower="-0.0199964" upper="0.0"/>
    <parent link="l_99"/>
    <child link="l_85"/>
    <axis xyz="0 1 0"/>
    <origin xyz="0.0 0.0 -0.0" rpy="0.0 -0.0 0.0"/>
  </joint>
  <link name="l_86">
    <inertial>
      <origin xyz="0.0 0.0 0.0" rpy="0.0 -0.0 0.0"/>
      <mass value="0.05262326784"/>
      <inertia ixx="1.0" ixy="0.0" ixz="0.0" iyy="1.0" iyz="0.0" izz="1.0"/>
    </inertial>
    <visual>
      <geometry>
        <mesh filename="objs/86.obj"/>
      </geometry>
      <origin xyz="0.0 0.0 0.0" rpy="0.0 -0.0 0.0"/>
    </visual>
  </link>
  <joint name="joint_revolute_99_86" type="prismatic">
    <limit effort="2000.0" velocity="2.0" lower="-0.0199964" upper="0.0"/>
    <parent link="l_99"/>
    <child link="l_86"/>
    <axis xyz="0 1 0"/>
    <origin xyz="0.0 0.0 -0.0" rpy="0.0 -0.0 0.0"/>
  </joint>
  <link name="l_87">
    <inertial>
      <origin xyz="0.0 0.0 0.0" rpy="0.0 -0.0 0.0"/>
      <mass value="0.10524653568"/>
      <inertia ixx="1.0" ixy="0.0" ixz="0.0" iyy="1.0" iyz="0.0" izz="1.0"/>
    </inertial>
    <visual>
      <geometry>
        <mesh filename="objs/87.obj"/>
      </geometry>
      <origin xyz="0.0 0.0 0.0" rpy="0.0 -0.0 0.0"/>
    </visual>
  </link>
  <joint name="joint_revolute_99_87" type="prismatic">
    <limit effort="2000.0" velocity="2.0" lower="-0.0199964" upper="0.0"/>
    <parent link="l_99"/>
    <child link="l_87"/>
    <axis xyz="0 1 0"/>
    <origin xyz="0.0 0.0 -0.0" rpy="0.0 -0.0 0.0"/>
  </joint>
  <link name="l_88">
    <inertial>
      <origin xyz="0.0 0.0 0.0" rpy="0.0 -0.0 0.0"/>
      <mass value="0.06219113472"/>
      <inertia ixx="1.0" ixy="0.0" ixz="0.0" iyy="1.0" iyz="0.0" izz="1.0"/>
    </inertial>
    <visual>
      <geometry>
        <mesh filename="objs/88.obj"/>
      </geometry>
      <origin xyz="0.0 0.0 0.0" rpy="0.0 -0.0 0.0"/>
    </visual>
  </link>
  <joint name="joint_revolute_99_88" type="prismatic">
    <limit effort="2000.0" velocity="2.0" lower="-0.0199964" upper="0.0"/>
    <parent link="l_99"/>
    <child link="l_88"/>
    <axis xyz="0 1 0"/>
    <origin xyz="0.0 0.0 -0.0" rpy="0.0 -0.0 0.0"/>
  </joint>
  <link name="l_89">
    <inertial>
      <origin xyz="0.0 0.0 0.0" rpy="0.0 -0.0 0.0"/>
      <mass value="0.06219113472"/>
      <inertia ixx="1.0" ixy="0.0" ixz="0.0" iyy="1.0" iyz="0.0" izz="1.0"/>
    </inertial>
    <visual>
      <geometry>
        <mesh filename="objs/89.obj"/>
      </geometry>
      <origin xyz="0.0 0.0 0.0" rpy="0.0 -0.0 0.0"/>
    </visual>
  </link>
  <joint name="joint_revolute_99_89" type="prismatic">
    <limit effort="2000.0" velocity="2.0" lower="-0.0199964" upper="0.0"/>
    <parent link="l_99"/>
    <child link="l_89"/>
    <axis xyz="0 1 0"/>
    <origin xyz="0.0 0.0 -0.0" rpy="0.0 -0.0 0.0"/>
  </joint>
  <link name="l_90">
    <inertial>
      <origin xyz="0.0 0.0 0.0" rpy="0.0 -0.0 0.0"/>
      <mass value="0.050231301119999995"/>
      <inertia ixx="1.0" ixy="0.0" ixz="0.0" iyy="1.0" iyz="0.0" izz="1.0"/>
    </inertial>
    <visual>
      <geometry>
        <mesh filename="objs/90.obj"/>
      </geometry>
      <origin xyz="0.0 0.0 0.0" rpy="0.0 -0.0 0.0"/>
    </visual>
  </link>
  <joint name="joint_revolute_99_90" type="prismatic">
    <limit effort="2000.0" velocity="2.0" lower="-0.0199964" upper="0.0"/>
    <parent link="l_99"/>
    <child link="l_90"/>
    <axis xyz="0 1 0"/>
    <origin xyz="0.0 0.0 -0.0" rpy="0.0 -0.0 0.0"/>
  </joint>
  <link name="l_91">
    <inertial>
      <origin xyz="0.0 0.0 0.0" rpy="0.0 -0.0 0.0"/>
      <mass value="0.0717590016"/>
      <inertia ixx="1.0" ixy="0.0" ixz="0.0" iyy="1.0" iyz="0.0" izz="1.0"/>
    </inertial>
    <visual>
      <geometry>
        <mesh filename="objs/91.obj"/>
      </geometry>
      <origin xyz="0.0 0.0 0.0" rpy="0.0 -0.0 0.0"/>
    </visual>
  </link>
  <joint name="joint_revolute_99_91" type="prismatic">
    <limit effort="2000.0" velocity="2.0" lower="-0.0199964" upper="0.0"/>
    <parent link="l_99"/>
    <child link="l_91"/>
    <axis xyz="0 1 0"/>
    <origin xyz="0.0 0.0 -0.0" rpy="0.0 -0.0 0.0"/>
  </joint>
  <link name="l_92">
    <inertial>
      <origin xyz="0.0 0.0 0.0" rpy="0.0 -0.0 0.0"/>
      <mass value="0.06219113472"/>
      <inertia ixx="1.0" ixy="0.0" ixz="0.0" iyy="1.0" iyz="0.0" izz="1.0"/>
    </inertial>
    <visual>
      <geometry>
        <mesh filename="objs/92.obj"/>
      </geometry>
      <origin xyz="0.0 0.0 0.0" rpy="0.0 -0.0 0.0"/>
    </visual>
  </link>
  <joint name="joint_revolute_99_92" type="prismatic">
    <limit effort="2000.0" velocity="2.0" lower="-0.0199964" upper="0.0"/>
    <parent link="l_99"/>
    <child link="l_92"/>
    <axis xyz="0 1 0"/>
    <origin xyz="0.0 0.0 -0.0" rpy="0.0 -0.0 0.0"/>
  </joint>
  <link name="l_93">
    <inertial>
      <origin xyz="0.0 0.0 0.0" rpy="0.0 -0.0 0.0"/>
      <mass value="0.043055400960000004"/>
      <inertia ixx="1.0" ixy="0.0" ixz="0.0" iyy="1.0" iyz="0.0" izz="1.0"/>
    </inertial>
    <visual>
      <geometry>
        <mesh filename="objs/93.obj"/>
      </geometry>
      <origin xyz="0.0 0.0 0.0" rpy="0.0 -0.0 0.0"/>
    </visual>
  </link>
  <joint name="joint_revolute_99_93" type="prismatic">
    <limit effort="2000.0" velocity="2.0" lower="-0.0199964" upper="0.0"/>
    <parent link="l_99"/>
    <child link="l_93"/>
    <axis xyz="0 1 0"/>
    <origin xyz="0.0 0.0 -0.0" rpy="0.0 -0.0 0.0"/>
  </joint>
  <link name="l_94">
    <inertial>
      <origin xyz="0.0 0.0 0.0" rpy="0.0 -0.0 0.0"/>
      <mass value="0.047839334399999996"/>
      <inertia ixx="1.0" ixy="0.0" ixz="0.0" iyy="1.0" iyz="0.0" izz="1.0"/>
    </inertial>
    <visual>
      <geometry>
        <mesh filename="objs/94.obj"/>
      </geometry>
      <origin xyz="0.0 0.0 0.0" rpy="0.0 -0.0 0.0"/>
    </visual>
  </link>
  <joint name="joint_revolute_99_94" type="prismatic">
    <limit effort="2000.0" velocity="2.0" lower="-0.0199964" upper="0.0"/>
    <parent link="l_99"/>
    <child link="l_94"/>
    <axis xyz="0 1 0"/>
    <origin xyz="0.0 0.0 -0.0" rpy="0.0 -0.0 0.0"/>
  </joint>
  <link name="l_95">
    <inertial>
      <origin xyz="0.0 0.0 0.0" rpy="0.0 -0.0 0.0"/>
      <mass value="0.059799168"/>
      <inertia ixx="1.0" ixy="0.0" ixz="0.0" iyy="1.0" iyz="0.0" izz="1.0"/>
    </inertial>
    <visual>
      <geometry>
        <mesh filename="objs/95.obj"/>
      </geometry>
      <origin xyz="0.0 0.0 0.0" rpy="0.0 -0.0 0.0"/>
    </visual>
  </link>
  <joint name="joint_revolute_99_95" type="prismatic">
    <limit effort="2000.0" velocity="2.0" lower="-0.0199964" upper="0.0"/>
    <parent link="l_99"/>
    <child link="l_95"/>
    <axis xyz="0 1 0"/>
    <origin xyz="0.0 0.0 -0.0" rpy="0.0 -0.0 0.0"/>
  </joint>
  <link name="l_96">
    <inertial>
      <origin xyz="0.0 0.0 0.0" rpy="0.0 -0.0 0.0"/>
      <mass value="0.05740720128"/>
      <inertia ixx="1.0" ixy="0.0" ixz="0.0" iyy="1.0" iyz="0.0" izz="1.0"/>
    </inertial>
    <visual>
      <geometry>
        <mesh filename="objs/96.obj"/>
      </geometry>
      <origin xyz="0.0 0.0 0.0" rpy="0.0 -0.0 0.0"/>
    </visual>
  </link>
  <joint name="joint_revolute_99_96" type="prismatic">
    <limit effort="2000.0" velocity="2.0" lower="-0.0199964" upper="0.0"/>
    <parent link="l_99"/>
    <child link="l_96"/>
    <axis xyz="0 1 0"/>
    <origin xyz="0.0 0.0 -0.0" rpy="0.0 -0.0 0.0"/>
  </joint>
  <link name="l_97">
    <inertial>
      <origin xyz="0.0 0.0 0.0" rpy="0.0 -0.0 0.0"/>
      <mass value="0.06219113472"/>
      <inertia ixx="1.0" ixy="0.0" ixz="0.0" iyy="1.0" iyz="0.0" izz="1.0"/>
    </inertial>
    <visual>
      <geometry>
        <mesh filename="objs/97.obj"/>
      </geometry>
      <origin xyz="0.0 0.0 0.0" rpy="0.0 -0.0 0.0"/>
    </visual>
  </link>
  <joint name="joint_revolute_99_97" type="prismatic">
    <limit effort="2000.0" velocity="2.0" lower="-0.0199964" upper="0.0"/>
    <parent link="l_99"/>
    <child link="l_97"/>
    <axis xyz="0 1 0"/>
    <origin xyz="0.0 0.0 -0.0" rpy="0.0 -0.0 0.0"/>
  </joint>
  <link name="l_98">
    <inertial>
      <origin xyz="0.0 0.0 0.0" rpy="0.0 -0.0 0.0"/>
      <mass value="0.06458310144"/>
      <inertia ixx="1.0" ixy="0.0" ixz="0.0" iyy="1.0" iyz="0.0" izz="1.0"/>
    </inertial>
    <visual>
      <geometry>
        <mesh filename="objs/98.obj"/>
      </geometry>
      <origin xyz="0.0 0.0 0.0" rpy="0.0 -0.0 0.0"/>
    </visual>
  </link>
  <joint name="joint_revolute_99_98" type="prismatic">
    <limit effort="2000.0" velocity="2.0" lower="-0.0199964" upper="0.0"/>
    <parent link="l_99"/>
    <child link="l_98"/>
    <axis xyz="0 1 0"/>
    <origin xyz="0.0 0.0 -0.0" rpy="0.0 -0.0 0.0"/>
  </joint>
</robot>
